Error logged at 2024-12-10 13:56:14
Traceback (most recent call last):
  File "D:\QABot\QA-Bot\QABot.py", line 42, in RunBot
    filesDict = QAObj.FindFiles()
  File "D:\QABot\QA-Bot\DailyQA_Object.py", line 26, in FindFiles
    raise ValueError("adad")
ValueError: adad


Error logged at 2024-12-10 14:00:41
Traceback (most recent call last):
  File "D:\QABot\QA-Bot\QABot.py", line 43, in RunBot
    filesDict = QAObj.FindFiles()
  File "D:\QABot\QA-Bot\DailyQA_Object.py", line 26, in FindFiles
    raise ValueError("dadadwwdxwc")
ValueError: dadadwwdxwc


Error logged at 2024-12-10 14:01:01
Traceback (most recent call last):
  File "D:\QABot\QA-Bot\QABot.py", line 43, in RunBot
    filesDict = QAObj.FindFiles()
  File "D:\QABot\QA-Bot\DailyQA_Object.py", line 26, in FindFiles
    raise ValueError("dadadwwdxwc")
ValueError: dadadwwdxwc


Error logged at 2024-12-10 14:01:21
Traceback (most recent call last):
  File "D:\QABot\QA-Bot\QABot.py", line 43, in RunBot
    filesDict = QAObj.FindFiles()
  File "D:\QABot\QA-Bot\DailyQA_Object.py", line 26, in FindFiles
    raise ValueError("dadadwwdxwc")
ValueError: dadadwwdxwc


Error logged at 2024-12-11 13:56:30
Traceback (most recent call last):
  File "d:\QABot\QA-Bot\QABot.py", line 64, in RunBot
    QAObj.CleanUpFiles(filesDict,ResultDict)
  File "d:\QABot\QA-Bot\DailyQA_Object.py", line 142, in CleanUpFiles
    os.rename(folder, self.ArchiveFolder)
FileNotFoundError: [WinError 3] The system cannot find the path specified: 'C:/Users/John/Desktop/Test - Copy\\DQA_Head_1' -> 'C:/DQA_Head/John/Desktop/Test\\DailyQA_DQA_Head_2024-12-11 13-56-22'


Error logged at 2024-12-11 13:56:47
Traceback (most recent call last):
  File "d:\QABot\QA-Bot\QABot.py", line 64, in RunBot
    QAObj.CleanUpFiles(filesDict,ResultDict)
  File "d:\QABot\QA-Bot\DailyQA_Object.py", line 142, in CleanUpFiles
    os.rename(folder, self.ArchiveFolder)
FileNotFoundError: [WinError 3] The system cannot find the path specified: 'C:/Users/John/Desktop/Test - Copy\\DQA_Head_1' -> 'C:/DQA_Head/John/Desktop/Test\\DailyQA_DQA_Head_2024-12-11 13-56-38'


Error logged at 2024-12-11 14:00:55
Traceback (most recent call last):
  File "D:\QABot\QA-Bot\QABot.py", line 64, in RunBot
    QAObj.CleanUpFiles(filesDict,ResultDict)
  File "D:\QABot\QA-Bot\DailyQA_Object.py", line 142, in CleanUpFiles
    os.rename(folder, self.ArchiveFolder)
FileNotFoundError: [WinError 3] The system cannot find the path specified: 'C:/Users/John/Desktop/Test - Copy\\DQA_Head_1' -> 'C:/DQA_Head/John/Desktop/Test\\DailyQA_DQA_Head_2024-12-11 14-00-45'


Error logged at 2024-12-11 14:13:59
Traceback (most recent call last):
  File "D:\QABot\QA-Bot\QABot.py", line 64, in RunBot
    QAObj.CleanUpFiles(filesDict,ResultDict)
  File "D:\QABot\QA-Bot\DailyQA_Object.py", line 142, in CleanUpFiles
    os.rename(folder, self.ArchiveFolder)
FileNotFoundError: [WinError 3] The system cannot find the path specified: 'C:\\Users\\John\\Desktop\\Test - Copy\\DQA_Head_1' -> 'C:/DQA_Head/John/Desktop/Test\\DailyQA_DQA_Head_2024-12-11 14-13-34'


Error logged at 2024-12-11 14:16:32
Traceback (most recent call last):
  File "D:\QABot\QA-Bot\QABot.py", line 64, in RunBot
    QAObj.CleanUpFiles(filesDict,ResultDict)
  File "D:\QABot\QA-Bot\DailyQA_Object.py", line 143, in CleanUpFiles
    os.rename(folder, self.ArchiveFolder)
FileNotFoundError: [WinError 3] The system cannot find the path specified: 'C:\\Users\\John\\Desktop\\Test - Copy\\DQA_Head_1' -> 'C:\\DQA_Head\\John\\Desktop\\Test\\DailyQA_DQA_Head_2024-12-11 14-16-18'


Error logged at 2024-12-11 14:22:13
Traceback (most recent call last):
  File "D:\QABot\QA-Bot\QABot.py", line 64, in RunBot
    QAObj.CleanUpFiles(filesDict,ResultDict)
  File "D:\QABot\QA-Bot\DailyQA_Object.py", line 146, in CleanUpFiles
    os.rename("Results_DailyQA_"+QAName+"_"+str(self.date.strftime("%Y-%m-%d_%H-%M-%S"))+".txt",os.path.join(self.ArchiveFolder,"Results_DailyQA_"+QAName+"_"+str(self.date.strftime("%Y-%m-%d_%H-%M-%S"))+".txt"))
OSError: [WinError 17] The system cannot move the file to a different disk drive: 'Results_DailyQA_DQA_Head_2024-12-11_14-21-59.txt' -> 'C:/Users/John/Desktop/Test\\DailyQA_DQA_Head_2024-12-11 14-21-59\\Results_DailyQA_DQA_Head_2024-12-11_14-21-59.txt'


Error logged at 2024-12-11 14:29:01
Traceback (most recent call last):
  File "D:\QABot\QA-Bot\QABot.py", line 64, in RunBot
    QAObj.CleanUpFiles(filesDict,ResultDict)
  File "D:\QABot\QA-Bot\DistortionQA_Object.py", line 94, in CleanUpFiles
    os.rename("DistortionQA_"+self.ScannerName+"_"+self.Date+".txt",os.path.join(self.ArchiveFolder,"DistortionQA_"+self.ScannerName+"_"+self.Date+".txt"))
OSError: [WinError 17] The system cannot move the file to a different disk drive: 'DistortionQA_Raigmore Hospital MRI 1_2024-12-11 14-28-53.txt' -> 'C:/Users/John/Desktop/Test - Copy\\DistortionQA_Raigmore Hospital MRI 1_2024-12-11 14-28-53\\DistortionQA_Raigmore Hospital MRI 1_2024-12-11 14-28-53.txt'


Error logged at 2025-04-29 13:46:24
Traceback (most recent call last):
  File "c:\Users\Johnt\Documents\QA-Bot\QABot.py", line 61, in RunBot
    filesDict = QAObj.FindFiles()
                ^^^^^^^^^^^^^^^^^
  File "c:\Users\Johnt\Documents\QA-Bot\DistortionQA_Object.py", line 34, in FindFiles
    LoadedDICOM = pydicom.read_file( DICOMFiles[0] )
                                     ~~~~~~~~~~^^^
IndexError: list index out of range


Error logged at 2025-04-29 13:46:25
Traceback (most recent call last):
  File "c:\Users\Johnt\Documents\QA-Bot\QABot.py", line 61, in RunBot
    filesDict = QAObj.FindFiles()
                ^^^^^^^^^^^^^^^^^
  File "c:\Users\Johnt\Documents\QA-Bot\DistortionQA_Object.py", line 34, in FindFiles
    LoadedDICOM = pydicom.read_file( DICOMFiles[0] )
                                     ~~~~~~~~~~^^^
IndexError: list index out of range


Error logged at 2025-04-29 13:46:26
Traceback (most recent call last):
  File "c:\Users\Johnt\Documents\QA-Bot\QABot.py", line 61, in RunBot
    filesDict = QAObj.FindFiles()
                ^^^^^^^^^^^^^^^^^
  File "c:\Users\Johnt\Documents\QA-Bot\DistortionQA_Object.py", line 34, in FindFiles
    LoadedDICOM = pydicom.read_file( DICOMFiles[0] )
                                     ~~~~~~~~~~^^^
IndexError: list index out of range


Error logged at 2025-04-29 13:46:28
Traceback (most recent call last):
  File "c:\Users\Johnt\Documents\QA-Bot\QABot.py", line 61, in RunBot
    filesDict = QAObj.FindFiles()
                ^^^^^^^^^^^^^^^^^
  File "c:\Users\Johnt\Documents\QA-Bot\DistortionQA_Object.py", line 34, in FindFiles
    LoadedDICOM = pydicom.read_file( DICOMFiles[0] )
                                     ~~~~~~~~~~^^^
IndexError: list index out of range


Error logged at 2025-04-29 13:46:29
Traceback (most recent call last):
  File "c:\Users\Johnt\Documents\QA-Bot\QABot.py", line 61, in RunBot
    filesDict = QAObj.FindFiles()
                ^^^^^^^^^^^^^^^^^
  File "c:\Users\Johnt\Documents\QA-Bot\DistortionQA_Object.py", line 34, in FindFiles
    LoadedDICOM = pydicom.read_file( DICOMFiles[0] )
                                     ~~~~~~~~~~^^^
IndexError: list index out of range


Error logged at 2025-04-29 13:46:30
Traceback (most recent call last):
  File "c:\Users\Johnt\Documents\QA-Bot\QABot.py", line 61, in RunBot
    filesDict = QAObj.FindFiles()
                ^^^^^^^^^^^^^^^^^
  File "c:\Users\Johnt\Documents\QA-Bot\DistortionQA_Object.py", line 34, in FindFiles
    LoadedDICOM = pydicom.read_file( DICOMFiles[0] )
                                     ~~~~~~~~~~^^^
IndexError: list index out of range


Error logged at 2025-04-29 13:46:31
Traceback (most recent call last):
  File "c:\Users\Johnt\Documents\QA-Bot\QABot.py", line 61, in RunBot
    filesDict = QAObj.FindFiles()
                ^^^^^^^^^^^^^^^^^
  File "c:\Users\Johnt\Documents\QA-Bot\DistortionQA_Object.py", line 34, in FindFiles
    LoadedDICOM = pydicom.read_file( DICOMFiles[0] )
                                     ~~~~~~~~~~^^^
IndexError: list index out of range


Error logged at 2025-04-29 14:37:40
Traceback (most recent call last):
  File "c:\Users\Johnt\anaconda3\Lib\shutil.py", line 847, in move
    os.rename(src, real_dst)
PermissionError: [WinError 32] The process cannot access the file because it is being used by another process: 'DistortionQA_Raigmore Hospital MRI 1_2025-04-29 14-37-23.txt' -> 'C:/Users/Johnt/Desktop/Output\\DistortionQA_Raigmore Hospital MRI 1_2025-04-29 14-37-23\\DistortionQA_Raigmore Hospital MRI 1_2025-04-29 14-37-23.txt'

During handling of the above exception, another exception occurred:

Traceback (most recent call last):
  File "C:\Users\Johnt\Documents\QA-Bot\QABot.py", line 83, in RunBot
    QAObj.CleanUpFiles(filesDict,ResultDict)
  File "C:\Users\Johnt\Documents\QA-Bot\DistortionQA_Object.py", line 137, in CleanUpFiles
    shutil.move("DistortionQA_"+self.ScannerName+"_"+self.Date+".txt",os.path.join(self.ArchiveFolder,"DistortionQA_"+self.ScannerName+"_"+self.Date+".txt"))
  File "c:\Users\Johnt\anaconda3\Lib\shutil.py", line 868, in move
    os.unlink(src)
PermissionError: [WinError 32] The process cannot access the file because it is being used by another process: 'DistortionQA_Raigmore Hospital MRI 1_2025-04-29 14-37-23.txt'


Error logged at 2025-04-29 14:57:34
Traceback (most recent call last):
  File "c:\Users\Johnt\Documents\QA-Bot\QABot.py", line 77, in RunBot
    QAObj.ReportData(filesDict,ResultDict)
  File "c:\Users\Johnt\Documents\QA-Bot\DailyQA_Object.py", line 88, in ReportData
    QA_Bot_Helper.UpdateTotalManHours(TimePerImage*NumberOfFilesLastRun)
  File "c:\Users\Johnt\Documents\QA-Bot\QA_Bot_Helper.py", line 61, in UpdateTotalManHours
    NewHours = CurrentHours+hours
               ~~~~~~~~~~~~^~~~~~
TypeError: can only concatenate str (not "float") to str


Error logged at 2025-04-29 14:57:34
Traceback (most recent call last):
  File "C:\Users\Johnt\anaconda3\Lib\shutil.py", line 847, in move
    os.rename(src, real_dst)
FileNotFoundError: [WinError 2] The system cannot find the file specified: 'Results_DailyQA_DQA_Head_2025-04-29_14-57-32.txt' -> 'C:/Users/Johnt/Desktop/Output\\DailyQA_DQA_Head_2025-04-29 14-57-32\\Results_DailyQA_DQA_Head_2025-04-29_14-57-32.txt'

During handling of the above exception, another exception occurred:

Traceback (most recent call last):
  File "c:\Users\Johnt\Documents\QA-Bot\QABot.py", line 83, in RunBot
    QAObj.CleanUpFiles(filesDict,ResultDict)
  File "c:\Users\Johnt\Documents\QA-Bot\DailyQA_Object.py", line 147, in CleanUpFiles
    shutil.move("Results_DailyQA_"+QAName+"_"+str(self.date.strftime("%Y-%m-%d_%H-%M-%S"))+".txt",os.path.join(self.ArchiveFolder,"Results_DailyQA_"+QAName+"_"+str(self.date.strftime("%Y-%m-%d_%H-%M-%S"))+".txt"))
  File "C:\Users\Johnt\anaconda3\Lib\shutil.py", line 867, in move
    copy_function(src, real_dst)
  File "C:\Users\Johnt\anaconda3\Lib\shutil.py", line 460, in copy2
    _winapi.CopyFile2(src_, dst_, flags)
FileNotFoundError: [WinError 2] The system cannot find the file specified


Error logged at 2025-04-29 15:02:36
Traceback (most recent call last):
  File "C:\Users\Johnt\Documents\QA-Bot\QABot.py", line 77, in RunBot
    QAObj.ReportData(filesDict,ResultDict)
  File "C:\Users\Johnt\Documents\QA-Bot\DailyQA_Object.py", line 88, in ReportData
    QA_Bot_Helper.UpdateTotalManHours(TimePerImage*NumberOfFilesLastRun)
  File "C:\Users\Johnt\Documents\QA-Bot\QA_Bot_Helper.py", line 65, in UpdateTotalManHours
    sh.worksheet("ManHoursLog").update( NewHours,"A1")
  File "c:\Users\Johnt\anaconda3\Lib\site-packages\gspread\worksheet.py", line 1242, in update
    response = self.client.values_update(
               ^^^^^^^^^^^^^^^^^^^^^^^^^^
  File "c:\Users\Johnt\anaconda3\Lib\site-packages\gspread\http_client.py", line 173, in values_update
    r = self.request("put", url, params=params, json=body)
        ^^^^^^^^^^^^^^^^^^^^^^^^^^^^^^^^^^^^^^^^^^^^^^^^^^
  File "c:\Users\Johnt\anaconda3\Lib\site-packages\gspread\http_client.py", line 128, in request
    raise APIError(response)
gspread.exceptions.APIError: APIError: [400]: Invalid value at 'data.values' (type.googleapis.com/google.protobuf.ListValue), 800.48200000000008


Error logged at 2025-04-29 15:02:36
Traceback (most recent call last):
  File "c:\Users\Johnt\anaconda3\Lib\shutil.py", line 847, in move
    os.rename(src, real_dst)
FileNotFoundError: [WinError 2] The system cannot find the file specified: 'Results_DailyQA_DQA_Head_2025-04-29_15-00-23.txt' -> 'C:/Users/Johnt/Desktop/Output\\DailyQA_DQA_Head_2025-04-29 15-00-23\\Results_DailyQA_DQA_Head_2025-04-29_15-00-23.txt'

During handling of the above exception, another exception occurred:

Traceback (most recent call last):
  File "C:\Users\Johnt\Documents\QA-Bot\QABot.py", line 83, in RunBot
    QAObj.CleanUpFiles(filesDict,ResultDict)
  File "C:\Users\Johnt\Documents\QA-Bot\DailyQA_Object.py", line 147, in CleanUpFiles
    shutil.move("Results_DailyQA_"+QAName+"_"+str(self.date.strftime("%Y-%m-%d_%H-%M-%S"))+".txt",os.path.join(self.ArchiveFolder,"Results_DailyQA_"+QAName+"_"+str(self.date.strftime("%Y-%m-%d_%H-%M-%S"))+".txt"))
  File "c:\Users\Johnt\anaconda3\Lib\shutil.py", line 867, in move
    copy_function(src, real_dst)
  File "c:\Users\Johnt\anaconda3\Lib\shutil.py", line 460, in copy2
    _winapi.CopyFile2(src_, dst_, flags)
FileNotFoundError: [WinError 2] The system cannot find the file specified


Error logged at 2025-04-29 15:08:33
Traceback (most recent call last):
  File "c:\Users\Johnt\Documents\QA-Bot\QABot.py", line 83, in RunBot
    QAObj.CleanUpFiles(filesDict,ResultDict)
  File "c:\Users\Johnt\Documents\QA-Bot\DailyQA_Object.py", line 150, in CleanUpFiles
    shutil.copyfile(os.path.join("DailyQA","DailyQA-main","Results",result[-1]+"_SmoothMethod.png"), os.path.join(self.ArchiveFolder,result[-1]+"_SmoothMethod.png"))
  File "C:\Users\Johnt\anaconda3\Lib\shutil.py", line 260, in copyfile
    with open(src, 'rb') as fsrc:
         ^^^^^^^^^^^^^^^
FileNotFoundError: [Errno 2] No such file or directory: 'DailyQA\\DailyQA-main\\Results\\Ax EPI-GRE head_SmoothMethod.png'


Error logged at 2025-04-29 15:24:13
Traceback (most recent call last):
  File "c:\Users\Johnt\Documents\QA-Bot\QABot.py", line 83, in RunBot
    QAObj.CleanUpFiles(filesDict,ResultDict)
  File "c:\Users\Johnt\Documents\QA-Bot\DailyQA_Object.py", line 150, in CleanUpFiles
    shutil.copyfile(os.path.join("DailyQA","DailyQA-main","Results",result[-1]+"_SmoothMethod.png"), os.path.join(self.ArchiveFolder,result[-1]+"_SmoothMethod.png"))
  File "C:\Users\Johnt\anaconda3\Lib\shutil.py", line 260, in copyfile
    with open(src, 'rb') as fsrc:
         ^^^^^^^^^^^^^^^
FileNotFoundError: [Errno 2] No such file or directory: 'DailyQA\\DailyQA-main\\Results\\Ax EPI-GRE head_SmoothMethod.png'


Error logged at 2025-04-29 15:55:27
Traceback (most recent call last):
  File "c:\Users\Johnt\Documents\QA-Bot\QABot.py", line 77, in RunBot
    QAObj.ReportData(filesDict,ResultDict)
  File "c:\Users\Johnt\Documents\QA-Bot\DailyQA_Object.py", line 60, in ReportData
    QAResult = Helper.DidQAPassV2(result)
               ^^^^^^^^^^^^^^^^^^^^^^^^^^
  File "c:\Users\Johnt\Documents\QA-Bot\DailyQACode\DailyQA-main\DQA_Scripts\Helper.py", line 436, in DidQAPassV2
    RelSNR = ROIResults[ROI][Slice]/ROIBaseline[ROI][Slice][0]
                                    ~~~~~~~~~~~~~~~~^^^^^^^
IndexError: list index out of range


Error logged at 2025-04-29 15:55:27
Traceback (most recent call last):
  File "c:\Users\Johnt\Documents\QA-Bot\QABot.py", line 83, in RunBot
    QAObj.CleanUpFiles(filesDict,ResultDict)
  File "c:\Users\Johnt\Documents\QA-Bot\DailyQA_Object.py", line 146, in CleanUpFiles
    shutil.move(folder, self.ArchiveFolder)
  File "C:\Users\Johnt\anaconda3\Lib\shutil.py", line 833, in move
    if os.path.isdir(dst):
       ^^^^^^^^^^^^^^^^^^
TypeError: _path_isdir: path should be string, bytes, os.PathLike or integer, not NoneType


Error logged at 2025-04-29 15:58:26
Traceback (most recent call last):
  File "c:\Users\Johnt\Documents\QA-Bot\QABot.py", line 77, in RunBot
    QAObj.ReportData(filesDict,ResultDict)
  File "c:\Users\Johnt\Documents\QA-Bot\DistortionQA_Object.py", line 109, in ReportData
    QA_Bot_Helper.SendEmail(TEXT,subject,images)
  File "c:\Users\Johnt\Documents\QA-Bot\QA_Bot_Helper.py", line 37, in SendEmail
    TEXT+="Estimated Total Man Hours Saved: " + str( round(QA_Bot_Helper.GetTotalManHoursSaved(),2)) + " hours\n\n"
                                                     ^^^^^^^^^^^^^^^^^^^^^^^^^^^^^^^^^^^^^^^^^^^^^^
TypeError: type str doesn't define __round__ method


Error logged at 2025-04-29 16:07:13
Traceback (most recent call last):
  File "c:\Users\Johnt\Documents\QA-Bot\QABot.py", line 71, in RunBot
    ResultDict = QAObj.RunAnalysis(filesDict)
                 ^^^^^^^^^^^^^^^^^^^^^^^^^^^^
  File "c:\Users\Johnt\Documents\QA-Bot\DistortionQA_Object.py", line 57, in RunAnalysis
    ComputeDistortion = Compute_Distortion.DistortionCalculation(files["folder"], self.ChosenSequence)
                       ^^^^^^^^^^^^^^^^^^^^^^^^^^^^^^^^^^^^^^^^^^^^^^^^^^^^^^^^^^^^^^^^^^^^^^^^^^^^^^
  File "C:\Users\Johnt\Documents\QA-Bot\DistortionQACode\Distortion-QA-main\Compute_Distortion.py", line 78, in __init__
    LoadedDICOM = pydicom.read_file( file )
                  ^^^^^^^^^^^^^^^^^^^^^^^^^
  File "C:\Users\Johnt\anaconda3\Lib\site-packages\pydicom\filereader.py", line 1029, in dcmread
    dataset = read_partial(
              ^^^^^^^^^^^^^
  File "C:\Users\Johnt\anaconda3\Lib\site-packages\pydicom\filereader.py", line 780, in read_partial
    preamble = read_preamble(fileobj, force)
               ^^^^^^^^^^^^^^^^^^^^^^^^^^^^^
  File "C:\Users\Johnt\anaconda3\Lib\site-packages\pydicom\filereader.py", line 724, in read_preamble
    raise InvalidDicomError(
pydicom.errors.InvalidDicomError: File is missing DICOM File Meta Information header or the 'DICM' prefix is missing from the header. Use force=True to force reading.


Error logged at 2025-04-29 16:07:16
Traceback (most recent call last):
  File "c:\Users\Johnt\Documents\QA-Bot\QABot.py", line 77, in RunBot
    QAObj.ReportData(filesDict,ResultDict)
  File "c:\Users\Johnt\Documents\QA-Bot\DistortionQA_Object.py", line 99, in ReportData
    TEXT+= "Max Interplate Distortion: " + str(round(ResultDict["Interplate Max Distortion"][0],2)) +"mm \n"
                                                     ~~~~~~~~~~^^^^^^^^^^^^^^^^^^^^^^^^^^^^^
TypeError: 'NoneType' object is not subscriptable


Error logged at 2025-04-29 16:07:19
Traceback (most recent call last):
  File "C:\Users\Johnt\anaconda3\Lib\shutil.py", line 847, in move
    os.rename(src, real_dst)
FileNotFoundError: [WinError 2] The system cannot find the file specified: 'DistortionQA_Raigmore Hospital MRI 1_2025-04-29 16-05-31.txt' -> 'C:/Users/Johnt/Desktop/Output\\DistortionQA_Raigmore Hospital MRI 1_2025-04-29 16-05-31\\DistortionQA_Raigmore Hospital MRI 1_2025-04-29 16-05-31.txt'

During handling of the above exception, another exception occurred:

Traceback (most recent call last):
  File "c:\Users\Johnt\Documents\QA-Bot\QABot.py", line 83, in RunBot
    QAObj.CleanUpFiles(filesDict,ResultDict)
  File "c:\Users\Johnt\Documents\QA-Bot\DistortionQA_Object.py", line 139, in CleanUpFiles
    shutil.move("DistortionQA_"+self.ScannerName+"_"+self.Date+".txt",os.path.join(self.ArchiveFolder,"DistortionQA_"+self.ScannerName+"_"+self.Date+".txt"))
  File "C:\Users\Johnt\anaconda3\Lib\shutil.py", line 867, in move
    copy_function(src, real_dst)
  File "C:\Users\Johnt\anaconda3\Lib\shutil.py", line 460, in copy2
    _winapi.CopyFile2(src_, dst_, flags)
FileNotFoundError: [WinError 2] The system cannot find the file specified


Error logged at 2025-05-15 14:31:32
Traceback (most recent call last):
  File "/Users/john/Documents/QA-Bot/QABot.py", line 105, in RunBot
    self.CheckDICOMHasRealName(filesDict)
  File "/Users/john/Documents/QA-Bot/QABot.py", line 63, in CheckDICOMHasRealName
    raise Exception("First name in DICOM was found in the database, please check the file")
Exception: First name in DICOM was found in the database, please check the file


Error logged at 2025-05-15 14:31:34
Traceback (most recent call last):
  File "/Users/john/Documents/QA-Bot/QABot.py", line 112, in RunBot
    QAObj.CleanUpFiles(filesDict,ResultDict)
  File "/Users/john/Documents/QA-Bot/DailyQA_Object.py", line 150, in CleanUpFiles
    shutil.move(folder, self.ArchiveFolder)
  File "/opt/anaconda3/envs/QABot/lib/python3.10/shutil.py", line 802, in move
    if os.path.isdir(dst):
  File "/opt/anaconda3/envs/QABot/lib/python3.10/genericpath.py", line 42, in isdir
    st = os.stat(s)
TypeError: stat: path should be string, bytes, os.PathLike or integer, not NoneType


Error logged at 2025-05-15 14:34:38
Traceback (most recent call last):
  File "/Users/john/Documents/QA-Bot/QABot.py", line 103, in RunBot
    self.CheckDICOMHasRealName(filesDict)
  File "/Users/john/Documents/QA-Bot/QABot.py", line 63, in CheckDICOMHasRealName
    raise Exception("First name in DICOM was found in the database, please check the file")
Exception: First name in DICOM was found in the database, please check the file


Error logged at 2025-05-15 14:38:02
Traceback (most recent call last):
  File "/Users/john/Documents/QA-Bot/QABot.py", line 96, in RunBot
    ResultDict = QAObj.RunAnalysis(filesDict)
  File "/Users/john/Documents/QA-Bot/DailyQA_Object.py", line 48, in RunAnalysis
    self.ArchiveFolder = "DailyQA_"+QAName+"_"+str(self.date.strftime("%Y-%m-%d %H-%M-%S"))
AttributeError: 'NoneType' object has no attribute 'strftime'


Error logged at 2025-05-15 14:38:02
Traceback (most recent call last):
  File "/Users/john/Documents/QA-Bot/QABot.py", line 103, in RunBot
    self.CheckDICOMHasRealName(filesDict)
  File "/Users/john/Documents/QA-Bot/QABot.py", line 63, in CheckDICOMHasRealName
    raise Exception("First name in DICOM was found in the database, please check the file")
Exception: First name in DICOM was found in the database, please check the file


Error logged at 2025-05-15 14:38:02
Traceback (most recent call last):
  File "/Users/john/Documents/QA-Bot/QABot.py", line 110, in RunBot
    QAObj.CleanUpFiles(filesDict,ResultDict)
  File "/Users/john/Documents/QA-Bot/DailyQA_Object.py", line 152, in CleanUpFiles
    Results = ResultDict["Results"]
TypeError: 'NoneType' object is not subscriptable


Error logged at 2025-05-15 14:43:27
Traceback (most recent call last):
  File "/Users/john/Documents/QA-Bot/QABot.py", line 96, in RunBot
    ResultDict = QAObj.RunAnalysis(filesDict)
  File "/Users/john/Documents/QA-Bot/DailyQA_Object.py", line 48, in RunAnalysis
    self.ArchiveFolder = "DailyQA_"+QAName+"_"+str(self.date.strftime("%Y-%m-%d %H-%M-%S"))
AttributeError: 'NoneType' object has no attribute 'strftime'


Error logged at 2025-05-15 14:43:27
Traceback (most recent call last):
  File "/Users/john/Documents/QA-Bot/QABot.py", line 103, in RunBot
    self.CheckDICOMHasRealName(filesDict)
  File "/Users/john/Documents/QA-Bot/QABot.py", line 63, in CheckDICOMHasRealName
    raise Exception("First name in DICOM was found in the database, please check the file")
Exception: First name in DICOM was found in the database, please check the file


Error logged at 2025-05-15 14:48:15
Traceback (most recent call last):
  File "/Users/john/Documents/QA-Bot/QABot.py", line 103, in RunBot
    self.CheckDICOMHasRealName(filesDict)
  File "/Users/john/Documents/QA-Bot/QABot.py", line 63, in CheckDICOMHasRealName
    raise Exception("First name in DICOM was found in the database, please check the file")
Exception: First name in DICOM was found in the database, please check the file


Error logged at 2025-05-15 14:48:22
Traceback (most recent call last):
  File "/opt/anaconda3/envs/QABot/lib/python3.10/shutil.py", line 816, in move
    os.rename(src, real_dst)
FileNotFoundError: [Errno 2] No such file or directory: 'Results_DailyQA_DQA_Head_2025-05-15_14-48-10.txt' -> 'Archive/DailyQA_DQA_Head_2025-05-15 14-48-10/Results_DailyQA_DQA_Head_2025-05-15_14-48-10.txt'

During handling of the above exception, another exception occurred:

Traceback (most recent call last):
  File "/Users/john/Documents/QA-Bot/QABot.py", line 110, in RunBot
    QAObj.CleanUpFiles(filesDict,ResultDict)
  File "/Users/john/Documents/QA-Bot/DailyQA_Object.py", line 161, in CleanUpFiles
    shutil.move("Results_DailyQA_"+QAName+"_"+str(self.date.strftime("%Y-%m-%d_%H-%M-%S"))+".txt",os.path.join(self.ArchiveFolder,"Results_DailyQA_"+QAName+"_"+str(self.date.strftime("%Y-%m-%d_%H-%M-%S"))+".txt"))
  File "/opt/anaconda3/envs/QABot/lib/python3.10/shutil.py", line 836, in move
    copy_function(src, real_dst)
  File "/opt/anaconda3/envs/QABot/lib/python3.10/shutil.py", line 434, in copy2
    copyfile(src, dst, follow_symlinks=follow_symlinks)
  File "/opt/anaconda3/envs/QABot/lib/python3.10/shutil.py", line 254, in copyfile
    with open(src, 'rb') as fsrc:
FileNotFoundError: [Errno 2] No such file or directory: 'Results_DailyQA_DQA_Head_2025-05-15_14-48-10.txt'


Error logged at 2025-05-15 14:57:46
Traceback (most recent call last):
  File "/Users/john/Documents/QA-Bot/QABot.py", line 103, in RunBot
    self.CheckDICOMHasRealName(filesDict)
  File "/Users/john/Documents/QA-Bot/QABot.py", line 63, in CheckDICOMHasRealName
    raise Exception("First name in DICOM was found in the database, please check the file")
Exception: First name in DICOM was found in the database, please check the file


